Workbook
Name acquisition: #REF!
Name circ: #REF!
Name circ2: #REF!

Sheet Income Statement
D3: GAMESTOP (NYSE: GME) | E3: << Enter company name
E5: Actual | J5: Projected | P5: Sensitivity Tables
D6: Year | E6: 44227 | F6: =EOMONTH(E6,12) -> 44592 | G6: =EOMONTH(F6,12) -> 44957 | H6: =EOMONTH(G6,12) -> 45322 | I6: =EOMONTH(H6,12) -> 45688 | J6: =EOMONTH(I6,12) -> 46053 | K6: =EOMONTH(J6,12) -> 46418 | L6: =EOMONTH(K6,12) -> 46783
D7: Projection Period | J7: =(J6-TODAY())/365 -> -0.23561644 | K7: =(K6-TODAY())/365 -> 0.76438356 | L7: =(L6-TODAY())/365 -> 1.7643836
P8: EV / EBITDA x WACC Effect on the Return Profile / Price
B9: x | D9: Net sales | E9: 5089.8 | F9: 6010.7 | G9: 5927.2 | H9: 5272.8 | I9: 3823 | J9: =+I9*(1+J10) -> 4033 | K9: =+J9*(1+K10) -> 4341.28 | L9: =+K9*(1+L10) -> 4633.1912 | O9: =TEXT(K93,"0.0%;(0.0%)")&" / "&TEXT(J93,"$0.00") -> 15.3% / $24.79 | P9: =+Q9-0.25 -> 4.25 | Q9: =+R9-0.25 -> 4.5 | R9: 4.75 | S9: =+R9+0.25 -> 5 | T9: =+S9+0.25 -> 5.25
D10: Sales Growth | F10: =(F9/E9)-1 -> 0.18093049 | G10: =(G9/F9)-1 -> -0.013891893 | H10: =(H9/G9)-1 -> -0.11040626 | I10: =(I9/H9)-1 -> -0.27495828 | J10: =OFFSET($I$103,MATCH($L$101,$D$104:$D$106,0),MATCH(J$6,$J$103:$L$103,0)) -> 0.054930683 | K10: =OFFSET($I$103,MATCH($L$101,$D$104:$D$106,0),MATCH(K$6,$J$103:$L$103,0)) -> 0.076439375 | L10: =OFFSET($I$103,MATCH($L$101,$D$104:$D$106,0),MATCH(L$6,$J$103:$L$103,0)) -> 0.067240814 | O10: 0.0811 | P10: (89.5%) / $2.25 | Q10: (88.4%) / $2.49 | R10: (87.3%) / $2.74 | S10: (86.1%) / $2.98 | T10: (85.0%) / $3.22
D11: Consensus Sales Growth | J11: -0.020562246 | K11: 0.015356075 | L11: 0.030351194 | O11: 0.0761 | P11: (89.3%) / $2.29 | Q11: (88.2%) / $2.54 | R11: (87.1%) / $2.78 | S11: (85.9%) / $3.03 | T11: (84.8%) / $3.27
O12: 0.0718 | P12: (89.2%) / $2.33 | Q12: (88.0%) / $2.58 | R12: (86.9%) / $2.82 | S12: (85.7%) / $3.07 | T12: (84.6%) / $3.32
D13: Cost of Goods Sold | E13: 3830.3 | F13: 4662.9 | G13: 4555.1 | H13: 4267 | I13: 2709 | J13: =J14*J9 -> 2811.001 | K13: =K14*K9 -> 3008.507 | L13: =L14*L9 -> 3196.9019 | O13: 0.0661 | P13: (88.9%) / $2.38 | Q13: (87.8%) / $2.63 | R13: (86.6%) / $2.88 | S13: (85.4%) / $3.13 | T13: (84.3%) / $3.38
D14: COGS Margin | E14: =E13/E9 -> 0.7525443 | F14: =F13/F9 -> 0.77576655 | G14: =G13/G9 -> 0.7685079 | H14: =H13/H9 -> 0.80924746 | I14: =I13/I9 -> 0.70860581 | J14: =OFFSET($I$108,MATCH($L$101,$D$109:$D$111,0),MATCH(J$6,$J$108:$L$108,0)) -> 0.697 | K14: =OFFSET($I$108,MATCH($L$101,$D$109:$D$111,0),MATCH(K$6,$J$108:$L$108,0)) -> 0.693 | L14: =OFFSET($I$108,MATCH($L$101,$D$109:$D$111,0),MATCH(L$6,$J$108:$L$108,0)) -> 0.69 | O14: 0.0611 | P14: (88.7%) / $2.42 | Q14: (87.6%) / $2.68 | R14: (86.4%) / $2.93 | S14: (85.2%) / $3.18 | T14: (84.0%) / $3.43
D15: Gross Profit | E15: =E9-E13 -> 1259.5 | F15: =F9-F13 -> 1347.8 | G15: =G9-G13 -> 1372.1 | H15: =H9-H13 -> 1005.8 | I15: =I9-I13 -> 1114 | J15: =J9-J13 -> 1221.999 | K15: =K9-K13 -> 1332.773 | L15: =L9-L13 -> 1436.2893
D16: Gross Profit Margin | E16: =E15/E9 -> 0.2474557 | F16: =F15/F9 -> 0.22423345 | G16: =G15/G9 -> 0.2314921 | H16: =H15/H9 -> 0.19075254 | I16: =I15/I9 -> 0.29139419 | J16: =J15/J9 -> 0.303 | K16: =K15/K9 -> 0.307 | L16: =L15/L9 -> 0.31
D18: Selling, general & administrative expenses | E18: 1514.2 | F18: 1656 | G18: 1630 | H18: 1246 | I18: 1075 | P18: 4159 | Q18: 4277
D19: Amortization of intangible assets | P19: =(P18/I9)-1 -> 0.087889092 | Q19: =(Q18/P18-1) -> 0.028372205
D20: Total Operating Expense | E20: =SUM(E18:E19) -> 1514.2 | F20: =SUM(F18:F19) -> 1656 | G20: =SUM(G18:G19) -> 1630 | H20: =SUM(H18:H19) -> 1246 | I20: =SUM(I18:I19) -> 1075 | J20: =J21*J9 -> 867.095 | K20: =K21*K9 -> 933.3752 | L20: =L21*L9 -> 991.50292
D21: Operating Expense Margin | E21: =E20/E9 -> 0.29749695 | F21: =F20/F9 -> 0.27550868 | G21: =G20/G9 -> 0.27500337 | H21: =H20/H9 -> 0.23630709 | I21: =I20/I9 -> 0.28119278 | J21: =OFFSET($I$113,MATCH($L$101,$D$114:$D$116,0),MATCH(J$6,$J$113:$L$113,0)) -> 0.215 | K21: =OFFSET($I$113,MATCH($L$101,$D$114:$D$116,0),MATCH(K$6,$J$113:$L$113,0)) -> 0.215 | L21: =OFFSET($I$113,MATCH($L$101,$D$114:$D$116,0),MATCH(L$6,$J$113:$L$113,0)) -> 0.214
D22: Operating Income (EBIT) | E22: =E15-E20 -> -254.7 | F22: =F15-F20 -> -308.2 | G22: =G15-G20 -> -257.9 | H22: =H15-H20 -> -240.2 | I22: =I15-I20 -> 39 | J22: =J15-J20 -> 354.904 | K22: =K15-K20 -> 399.39776 | L22: =L15-L20 -> 444.78636
D23: EBIT Margin | E23: =E22/E9 -> -0.050041259 | F23: =F22/F9 -> -0.051275226 | G23: =G22/G9 -> -0.04351127 | H23: =H22/H9 -> -0.045554544 | I23: =I22/I9 -> 0.010201413 | J23: =J22/J9 -> 0.088 | K23: =K22/K9 -> 0.092 | L23: =L22/L9 -> 0.096
D25: Interest expense | E25: -27.2 | F25: -32.1 | G25: -26.9 | H25: 9.5 | I25: 49.5 | J25: =J76*J73 -> 0.264 | K25: =K76*K73 -> 0.264 | L25: =L76*L73 -> 0.264
D26: Other Expense
D27: EBT | E27: =E22-E25-E26 -> -227.5 | F27: =F22-F25-F26 -> -276.1 | G27: =G22-G25-G26 -> -231 | H27: =H22-H25-H26 -> -249.7 | I27: =I22-I25-I26 -> -10.5 | J27: =J22-J25-J26 -> 354.64 | K27: =K22-K25-K26 -> 399.13376 | L27: =L22-L25-L26 -> 444.52236
D29: Income Tax Expense (Provision) | E29: -55 | F29: -14 | G29: 11 | H29: 6 | I29: 6 | J29: =J30*J27 -> 7.0928 | K29: =K30*K27 -> 11.974013 | L29: =L30*L27 -> 15.558282
D30: Tax Rate | E30: =E29/E27 -> 0.24175824 | F30: =F29/F27 -> 0.050706266 | G30: =G29/G27 -> -0.047619048 | H30: =H29/H27 -> -0.024028835 | I30: =I29/I27 -> -0.57142857 | J30: 0.02 | K30: 0.03 | L30: 0.035
D31: Net Income | E31: =E27-E29 -> -172.5 | F31: =F27-F29 -> -262.1 | G31: =G27-G29 -> -242 | H31: =H27-H29 -> -255.7 | I31: =I27-I29 -> -16.5 | J31: =J27-J29 -> 347.5472 | K31: =K27-K29 -> 387.15975 | L31: =L27-L29 -> 428.96407
D32: Net Income Margin | E32: =E31/E9 -> -0.033891312 | F32: =F31/F9 -> -0.04360557 | G32: =G31/G9 -> -0.040828722 | H32: =H31/H9 -> -0.048494159 | I32: =I31/I9 -> -0.0043159822 | J32: =J31/J9 -> 0.086175849 | K32: =K31/K9 -> 0.089181013 | L32: =L31/L9 -> 0.092585014
R33: commentary
D34: # diluted shares (in millions) | E34: 261.2 | F34: 303.6 | G34: 304.6 | H34: 305.7 | I34: 447 | J34: =I34+J35 -> 447 | K34: =J34+K35 -> 447 | L34: =K34+L35 -> 447 | R34: understabd movement
D35: Change in share count | F35: =F34-E34 -> 42.4 | G35: =G34-F34 -> 1 | H35: =H34-G34 -> 1.1 | I35: =I34-H34 -> 141.3 | J35: 0 | K35: 0 | L35: 0 | R35: MOVE BEAR OUT OF MIDDLE RANGE
D36: Earnings Per Share (GAAP) | E36: =E31/E34 -> -0.66041348 | F36: =F31/F34 -> -0.86330698 | G36: =G31/G34 -> -0.79448457 | H36: =H31/H34 -> -0.83644096 | I36: =I31/I34 -> -0.036912752 | J36: =J31/J34 -> 0.77751051 | K36: =K31/K34 -> 0.86612919 | L36: =L31/L34 -> 0.95965117
D37: EPS Growth | F37: =(F36-E36)/E36 -> 0.30722194 | G37: =(G36-F36)/F36 -> -0.079719514 | H37: =(H36-G36)/G36 -> 0.052809566 | I37: =(I36-H36)/H36 -> -0.95586927 | J37: =(J36-I36)/I36 -> -22.063467 | K37: =(K36-J36)/J36 -> 0.11397746 | L37: =(L36-K36)/K36 -> 0.10797694
D38: Earnings Per Share (adj.) | E38: 4.709 | F38: 2.153 | G38: 3.813 | H38: 1.03 | I38: 0.02 | J38: 0.33 | K38: 0.75 | L38: 0.36
D39: Adj. EPS Growth | F39: =(F38-E38)/E38 -> -0.5427904 | G39: =(G38-F38)/F38 -> 0.77101719 | H39: =(H38-G38)/G38 -> -0.72987149 | I39: =(I38-H38)/H38 -> -0.98058252 | J39: =(J38-I38)/I38 -> 15.5 | K39: =(K38-J38)/J38 -> 1.2727273 | L39: =(L38-K38)/K38 -> -0.52
D40: Consensus EPS (adj.) | J40: 0.075 | K40: 0.36 | L40: 0.4
D41: Consensus EPS (GAAP) | J41: 0.75 | K41: 0.36 | L41: n/a
D44: EBITDA | E44: =E22+E62 -> -174 | F44: =F22+F62 -> -231 | G44: =G22+G62 -> -196.2 | H44: =H22+H62 -> -181.2 | I44: =I22+I62 -> 78 | J44: =J22+J62 -> 395.234 | K44: =K22+K62 -> 447.15184 | L44: =L22+L62 -> 500.38465
D45: EBITDA Margin | E45: =E44/E9 -> -0.034186019 | F45: =F44/F9 -> -0.038431464 | G45: =G44/G9 -> -0.033101633 | H45: =H44/H9 -> -0.034365043 | I45: =I44/I9 -> 0.020402825 | J45: =J44/J9 -> 0.098 | K45: =K44/K9 -> 0.103 | L45: =L44/L9 -> 0.108
D47: Total Adjustments | E47: 166.8 | F47: -149.4 | G47: -236.9 | H47: -192.7 | I47: 64.7 | J47: =E47+F47+G47+H47+I47/5 -> -399.26 | K47: =F47+G47+H47+I47+J47/5 -> -594.152 | L47: =G47+H47+I47+J47+K47/5 -> -882.9904
D48: Adjusted EBITDA | E48: =E44+E47 -> -7.2 | F48: =F44+F47 -> -380.4 | G48: =G44+G47 -> -433.1 | H48: =H44+H47 -> -373.9 | I48: =I44+I47 -> 142.7 | J48: =J44+J47 -> -4.026 | K48: =K44+K47 -> -147.00016 | L48: =L44+L47 -> -382.60575
D49: Adj. EBITDA Margin | E49: =E48/E9 -> -0.0014145939 | F49: =F48/F9 -> -0.063287138 | G49: =G48/G9 -> -0.073069915 | H49: =H48/H9 -> -0.070911091 | I49: =I48/I9 -> 0.037326707 | J49: =J48/J9 -> -0.00099826432 | K49: =K48/K9 -> -0.033861018 | L49: =L48/L9 -> -0.082579314
...

Sheet Football Field
B3: {=D4+K23z} -> #NAME? | C3: ='Income Statement'!D3 -> GAMESTOP (NYSE: GME)
C4: Football Field Analysis
C7: EDIT | I7: DO NOT EDIT
D9: Valuation | F9: Range | I9: Valuation | K9: Range
C10: Type | D10: Methodology | F10: Low | G10: High | I10: Selection | K10: Low | L10: Difference | M10: High
C12: Analyst Research | D12: Price Targets | F12: 13.64 | G12: 14.18 | I12: =+C12 -> Analyst Research | K12: =+F12 -> 13.64 | L12: =M12-K12 -> 0.54 | M12: =G12 -> 14.18
C13: 52-Week Low/High | D13: 52-Week Low/High | F13: 20.73 | G13: 35.81 | I13: =+C13 -> 52-Week Low/High | K13: =F13 -> 20.73 | L13: =M13-K13 -> 15.08 | M13: =G13 -> 35.81
C14: DCF | D14: 2027E EBITDA Exit Method (4.5x - 5.0x) / Discount Rate (7.1% - 7.6%) | F14: 11.91 | G14: 120 | I14: =+C14 -> DCF | K14: =F14 -> 11.91 | L14: =M14-K14 -> 108.09 | M14: =G14 -> 120
C15: Comparables EV/EBITDA | D15: FY1 EV / EBITDA (4.5x - 5.0x) | F15: =+' Comps Valuation'!J33 -> 3.0853535 | G15: =+' Comps Valuation'!J34 -> 3.5274497 | I15: =+C15 -> Comparables EV/EBITDA | K15: =F15 -> 3.0853535 | L15: =M15-K15 -> 0.4420962 | M15: =G15 -> 3.5274497
C16: Comparables P/E | D16: FY1 P/E (10.00x - 11.00x) | F16: =+' Comps Valuation'!J38 -> 7.7751051 | G16: =+' Comps Valuation'!J39 -> 8.5526157 | I16: =+C16 -> Comparables P/E | K16: =F16 -> 7.7751051 | L16: =M16-K16 -> 0.77751051 | M16: =G16 -> 8.5526157

Sheet Revenue Build
C3: ='Income Statement'!D3 -> GAMESTOP (NYSE: GME)
D5: Actual | I5: Projected
D6: =+'Income Statement'!E6 -> 44227 | E6: =EOMONTH(D6,12) -> 44592 | F6: =EOMONTH(E6,12) -> 44957 | G6: =EOMONTH(F6,12) -> 45322 | H6: =EOMONTH(G6,12) -> 45688 | I6: =EOMONTH(H6,12) -> 46053 | J6: =EOMONTH(I6,12) -> 46418 | K6: =EOMONTH(J6,12) -> 46783
C10: Hardware And accessories | D10: 2531 | E10: 3172 | F10: 3140 | G10: 2997 | H10: 2100 | I10: =H10*(1+I11) -> 2310 | J10: =I10*(1+J11) -> 2494.8 | K10: =J10*(1+K11) -> 2669.436
C11: E-Systems Growth | E11: =IFERROR((E10/D10)-1,0) -> 0.25325958 | F11: =IFERROR((F10/E10)-1,0) -> -0.010088272 | G11: =IFERROR((G10/F10)-1,0) -> -0.045541401 | H11: =IFERROR((H10/G10)-1,0) -> -0.2992993 | I11: 0.1 | J11: 0.08 | K11: 0.07
C13: Software | D13: 1979 | E13: 2015 | F13: 1823 | G13: 1522 | H13: 1005 | I13: 1005 | J13: =I13*(1+J14) -> 1085.4 | K13: =J13*(1+K14) -> 1172.232
C14: [ New Segment] Growth | E14: =IFERROR((E13/D13)-1,0) -> 0.018191006 | F14: =IFERROR((F13/E13)-1,0) -> -0.09528536 | G14: =IFERROR((G13/F13)-1,0) -> -0.16511245 | H14: =IFERROR((H13/G13)-1,0) -> -0.33968463 | I14: 0.12 | J14: 0.08 | K14: 0.08
C16: Collectibles | D16: 580 | E16: 824 | F16: 965 | G16: 754 | H16: 718 | I16: 718 | J16: =I16*(1+J17) -> 761.08 | K16: =J16*(1+K17) -> 791.5232
C17: [ New Segment] Growth | E17: =IFERROR((E16/D16)-1,0) -> 0.42068966 | F17: =IFERROR((F16/E16)-1,0) -> 0.1711165 | G17: =IFERROR((G16/F16)-1,0) -> -0.21865285 | H17: =IFERROR((H16/G16)-1,0) -> -0.047745358 | I17: 0.08 | J17: 0.06 | K17: 0.04
C19: Total Revenue | D19: =SUM(D10,D13,D16) -> 5090 | E19: =SUM(E10,E13,E16) -> 6011 | F19: =SUM(F10,F13,F16) -> 5928 | G19: =SUM(G10,G13,G16) -> 5273 | H19: =SUM(H10,H13,H16) -> 3823 | I19: =SUM(I10,I13,I16) -> 4033 | J19: =SUM(J10,J13,J16) -> 4341.28 | K19: =SUM(K10,K13,K16) -> 4633.1912
C20: Total Revenue Growth | E20: =(E19/D19)-1 -> 0.18094303 | F20: =(F19/E19)-1 -> -0.013808019 | G20: =(G19/F19)-1 -> -0.11049258 | H20: =(H19/G19)-1 -> -0.27498578 | I20: =(I19/H19)-1 -> 0.054930683 | J20: =(J19/I19)-1 -> 0.076439375 | K20: =(K19/J19)-1 -> 0.067240814
C23: Seating (% Revenue) | D23: 0.75 | E23: 0.75 | F23: 0.75 | G23: 0.75 | H23: 0.75 | I23: =I10/I19 -> 0.57277461 | J23: =J10/J19 -> 0.57466922 | K23: =K10/K19 -> 0.57615494
C24: E-Systems (% Revenue) | D24: 0.25 | E24: 0.25 | F24: 0.25 | G24: 0.25 | H24: 0.25 | I24: =I10/I19 -> 0.57277461 | J24: =J10/J19 -> 0.57466922 | K24: =K10/K19 -> 0.57615494
C25: [Insert New Segment Here] (% Revenue) | D25: 0 | E25: 0 | F25: 0 | G25: 0 | H25: 0 | I25: =I13/I19 -> 0.24919415 | J25: =J13/J19 -> 0.25001843 | K25: =K13/K19 -> 0.25300747
C26: [Insert New Segment Here] (% Revenue) | D26: 0 | E26: 0 | F26: 0 | G26: 0 | H26: 0 | I26: =I16/I19 -> 0.17803124 | J26: =J16/J19 -> 0.17531235 | K26: =K16/K19 -> 0.17083759

Sheet Cash Flow Statement
C3: ='Income Statement'!D3 -> GAMESTOP (NYSE: GME)
C5: Cash Flow Statement | D5: Actual
C6: Report Date | D6: =+'Income Statement'!E6 -> 44227 | E6: =EOMONTH(D6,12) -> 44592 | F6: =EOMONTH(E6,12) -> 44957 | G6: =EOMONTH(F6,12) -> 45322 | H6: =EOMONTH(G6,12) -> 45688
C8: Net Income | D8: ='Income Statement'!E31 -> -172.5 | E8: ='Income Statement'!F31 -> -262.1 | F8: ='Income Statement'!G31 -> -242 | G8: ='Income Statement'!H31 -> -255.7 | H8: 541.8
C9: net income / loss | D9: -470.9 | E9: -215.3 | F9: -381.3 | G9: -313.1 | H9: 6.7
C10: adjustments to reconcile net income / loss | D10: 554 | E10: 155.6 | F10: 121.7 | G10: 104.4 | H10: 84.6
C11: changes in operating assets and liabilities | D11: -510.8 | E11: 183.9 | F11: -172.7 | G11: 288.9 | H11: -293
C12: Net Cash Flows Used In / Provided By Operating Activities | D12: =SUM(D9:D11) -> -427.7 | E12: =SUM(E9:E11) -> 124.2 | F12: =SUM(F9:F11) -> -432.3 | G12: =SUM(G9:G11) -> 80.2 | H12: =SUM(H9:H11) -> -201.7
C14: Other Investing Activities (Net) | D14: 17.6 | E14: 96.9 | F14: -2.8 | G14: 82.5 | H14: 15.9
C15: Proceeds from sales of marketable securities | D15: 0 | E15: 0 | F15: 0 | G15: -276.8 | H15: -326.8
C16: Purchases of marketable securities | D16: 0 | E16: 0 | F16: 0 | G16: 27.5 | H16: 312.6
C17: Purchase of property and equipment | D17: -78.5 | E17: -60 | F17: -62 | G17: -55.9 | H17: -34.9
C18: Net Cash Flows Used In / Provided By Investing Activities | D18: =SUM(D14:D17) -> -60.9 | E18: =SUM(E14:E17) -> 36.9 | F18: =SUM(F14:F17) -> -64.8 | G18: =SUM(G14:G17) -> -222.7 | H18: =SUM(H14:H17) -> -33.2
C20: Issuance of common stock, net | D20: 0 | E20: 0 | F20: 1672.8 | G20: 0 | H20: 0
C21: Repayments of senior notes | D21: -404.5 | E21: -130.3 | F21: -307.4 | G21: 0 | H21: 0
C22: Dividends paid | D22: -40.5 | E22: -0.3 | F22: 0 | G22: 0 | H22: 0
C23: Other Financing Activities (Net) | D23: -199.7 | E23: 75.2 | F23: -164.8 | G23: -7.9 | H23: -11.6
C24: Net Cash Flows Used In / Provided By Financing Activities | D24: =SUM(D20:D23) -> -644.7 | E24: =SUM(E20:E23) -> -55.4 | F24: =SUM(F20:F23) -> 1200.6 | G24: =SUM(G20:G23) -> -7.9 | H24: =SUM(H20:H23) -> -11.6
C27: Exchange rate effect on cash | D27: -6.9 | E27: 16.3 | F27: -16.6 | G27: -1.5 | H27: -8.6
C28: Net Change in Cash, Cash Equivalents, and Restricted Cash | D28: -1140.2 | E28: 122 | F28: 686.9 | G28: -151.9 | H28: -255.1
C29: Cash, Cash Equivalents, and Restricted Cash at Beginning of Period | D29: 1640.5 | E29: 513.5 | F29: 635 | G29: 1319 | H29: 1196
C30: Cash, Cash Equivalents, and Restricted Cash at End of Period | D30: 500.3 | E30: 635.5 | F30: 1321.9 | G30: 1168 | H30: 940.9

Sheet Balance Sheet
C3: ='Income Statement'!D3 -> GAMESTOP (NYSE: GME) | G3: d
C5: Balance Sheet | D5: Actual
C6: Year | D6: =+'Income Statement'!E6 -> 44227 | E6: =EOMONTH(D6,12) -> 44592 | F6: =EOMONTH(E6,12) -> 44957 | G6: =EOMONTH(F6,12) -> 45322 | H6: =EOMONTH(G6,12) -> 45688
C8: Assets
C10: Current Assets
C11: Cash & cash equivalents | D11: 499.4 | E11: 508.5 | F11: 1271.4 | G11: 1139 | H11: 921.7
C12: Accounts receivable | D12: 141.9 | E12: 105.3 | F12: 141.1 | G12: 153.9 | H12: 91
C13: Raw materials | D13: 859.7 | E13: 602.5 | F13: 915 | G13: 682.9 | H13: 632.5
C14: Other current assets | D14: 120.9 | E14: 334.9 | F14: 271.3 | G14: 96.3 | H14: 51.4
C15: Total Current Assets | D15: 1633.7 | E15: 1551.2 | F15: 2598.8 | G15: 2323.7 | H15: 1974.2
C17: Non-Current Assets
C18: Property and equipment, net | D18: 275.9 | E18: 201.2 | F18: 163.6 | G18: 136.5 | H18: 94.9
C19: Goodwill | D19: 0 | E19: 0 | F19: 0 | G19: 0 | H19: 0
C20: Operating lease right-of-use assets | D20: 767 | E20: 662.1 | F20: 586.6 | G20: 560.8 | H20: 555.8
C21: Other noncurrent assets | D21: 143.1 | E21: 58.1 | F21: 150.3 | G21: 92.4 | H21: 84.1
C22: Total Noncurrent Assets | D22: 1186 | E22: 921.4 | F22: 900.5 | G22: 789.7 | H22: 734.8
C23: Total Non-Current Assets | D23: 2819.7 | E23: 2472.6 | F23: 3499.3 | G23: 3113.4 | H23: 2709
C25: Total Assets | D25: =SUM(D23,D15) -> 4453.4 | E25: =SUM(E23,E15) -> 4023.8 | F25: =SUM(F23,F15) -> 6098.1 | G25: =SUM(G23,G15) -> 5437.1 | H25: =SUM(H23,H15) -> 4683.2
C27: Liabilities & Shareholder Equity
C29: Current Liabilities
C30: Accounts payable | D30: 380.8 | E30: 341.8 | F30: 471 | G30: 531.3 | H30: 324
C31: Accrued liabilities | D31: 0 | E31: 0 | F31: 0 | G31: 0 | H31: 0
C32: Operating lease liabilities (Current) | D32: 239.4 | E32: 227.4 | F32: 210.7 | G32: 194.7 | H32: 187.7
C33: Other current liabilities | D33: 617.5 | E33: 748.5 | F33: 673 | G33: 613.1 | H33: 422.8
C34: Total Current Liabilities | D34: 1237.7 | E34: 1342.7 | F34: 1354.7 | G34: 1339.1 | H34: 934.5
C35: Total Current Liabilities | D35: =D34 -> 1237.7 | E35: =E34 -> 1342.7 | F35: =F34 -> 1354.7 | G35: =G34 -> 1339.1 | H35: =H34 -> 934.5
C37: Non-Current Liabilities
C38: Operating lease liabilities (Noncurrent) | D38: 529.3 | E38: 456.7 | F38: 393.7 | G38: 382.4 | H38: 386.6
C39: Other noncurrent liabilities | D39: 21.4 | E39: 20.5 | F39: 107.9 | G39: 40.9 | H39: 31.6
C40: Total Non-Current Liabilities | D40: 970.5 | E40: 693.2 | F40: 542.1 | G40: 452 | H40: 435.9
C42: Total Liabilities | D42: =SUM(D40,D35) -> 2208.2 | E42: =SUM(E40,E35) -> 2035.9 | F42: =SUM(F40,F35) -> 1896.8 | G42: =SUM(G40,G35) -> 1791.1 | H42: =SUM(H40,H35) -> 1370.4
C44: Common stock | D44: 0.1 | E44: 0.1 | F44: 0.1 | G44: 0.1 | H44: 0.1
C45: Additional paid-in capital | D45: 0 | E45: 11 | F45: 1577.5 | G45: 1613.6 | H45: 1634.9
C46: Accumulated deficit | D46: 690.2 | E46: 474.9 | F46: 93.6 | G46: -219.5 | H46: -212.8
C47: Other comprehensive income / loss | D47: -78.8 | E47: -49.3 | F47: -68.7 | G47: -71.9 | H47: -83.6
C48: Total equity | D48: =SUM(D44:D47) -> 611.5 | E48: =SUM(E44:E47) -> 436.7 | F48: =SUM(F44:F47) -> 1602.5 | G48: =SUM(G44:G47) -> 1322.3 | H48: =SUM(H44:H47) -> 1338.6
C50: Total Liabilities and Shareholder Equity | D50: =SUM(D48,D42) -> 2819.7 | E50: =SUM(E48,E42) -> 2472.6 | F50: =SUM(F48,F42) -> 3499.3 | G50: =SUM(G48,G42) -> 3113.4 | H50: =SUM(H48,H42) -> 2709
C51: Check | D51: =ROUND(D23-D50,0) -> 0 | E51: =ROUND(E23-E50,0) -> 0 | F51: =ROUND(F23-F50,0) -> 0 | G51: =ROUND(G23-G50,0) -> 0 | H51: =ROUND(H23-H50,0) -> 0

Sheet Comps Financials
G3: Revenue | H3: EPS | J3: FY1 | K3: FY1 | O3: Net
E4: Market | F4: Enterprise | G4: Growth | H4: Growth | I4: FY1 | J4: EBITDA | K4: Pretax | L4: FY1 | M4: FY1 | O4: Debt / | P4: Debt/
C5: Company | D5: Ticker | E5: Cap | F5: Value | G5: YoY | H5: YoY | I5: EBITDA | J5: Margin | K5: Margin | L5: ROA | M5: ROE | N5: Div. Yield | O5: EBITDA | P5: Com Eq
C7: ='Income Statement'!D3 -> GAMESTOP (NYSE: GME) | D7: GME | E7: 9663.7588 | F7: 5126.7588 | G7: -0.1547 | H7: 4.6749 | I7: 169.9 | L7: 0.046 | M7: 0.0757 | N7: 0 | O7: -25.19 | P7: 0.8534
C10: Best Buy Co | D10: BBY-US | E10: 16944.07 | F10: 16242.078 | G10: -0.0220749 | H10: -0.374308 | I10: 2575 | J10: 0.0632 | K10: 0.0433 | L10: 0.05039 | M10: 0.2672 | N10: -0.052 | O10: 0.85 | P10: 1.5007
C11: JB Hi-Fi | D11: JBH-AU | E11: 6873.45 | F11: 6691.486 | G11: 0.08747 | H11: 0.0423 | I11: 679.94 | J11: 0.0917 | K11: 0.0652 | L11: 0.116 | M11: 0.2912 | N11: -0.06 | O11: 0.4 | P11: 0.4419
C12: Woolworths Group | D12: WOW-AU | E12: 22519.255 | F12: 25330.7 | G12: 0.0051213 | H12: 7.797 | I12: 3519.2 | J12: 0.0846 | K12: 0.0312 | L12: 0.028 | M12: 0.1875 | N12: -0.036 | O12: 3 | P12: 3.5771
C13: target | D13: TGT | E13: 42043.35 | F13: 54158.35 | G13: -0.01547064 | H13: -0.1143 | I13: 7975 | J13: 0.0764 | K13: 0.0441 | L13: 0.069 | M13: 0.2631 | N13: -0.033 | O13: 2.01 | P13: 1.319
C14: Fnac Darty SA | D14: FNAC.PA | E14: 1003.66 | F14: 2191.322 | G14: 0.1862 | H14: -0.8441 | I14: 804.45 | J14: 0.0568 | K14: 0.0126 | L14: 0.0032 | M14: 0.0154 | N14: -0.06 | O14: 3.45 | P14: 1.811
C15: ceconomy AG | D15: CECG.DE | E15: 2504.36 | F15: 4504.203 | G15: 0.0163 | H15: -1.0346 | I15: 818.69 | J15: 0.049 | K15: 0.01438 | L15: 0.0003 | M15: 0.006 | N15: -0.025 | O15: 2.4 | P15: 4.95
C16: Nintendo | D16: NTDOY | E16: 105705.09 | F16: 91495.833 | G16: 0.255 | H16: 0.1345 | I16: 2164.81 | J16: 0.2136 | K16: 0.2558 | L16: 0.11 | M16: 0.138 | N16: -0.026 | O16: -6.4 | P16: 0.018
B20: 0 | C20: Minimum | E20: =QUARTILE(E$10:E$18,$B20) -> 1003.66 | F20: =QUARTILE(F$10:F$18,$B20) -> 2191.322 | G20: =QUARTILE(G$10:G$18,$B20) -> -0.0220749 | H20: =QUARTILE(H$10:H$18,$B20) -> -1.0346 | I20: =QUARTILE(I$10:I$18,$B20) -> 679.94 | J20: =QUARTILE(J$10:J$18,$B20) -> 0.049 | K20: =QUARTILE(K$10:K$18,$B20) -> 0.0126 | L20: =QUARTILE(L$10:L$18,$B20) -> 0.0003 | ... P20: =QUARTILE(P$10:P$18,$B20) -> 0.018
B21: =+B20+1 -> 1 | C21: First Quartile | E21: =QUARTILE(E$10:E$18,$B21) -> 4688.905 | F21: =QUARTILE(F$10:F$18,$B21) -> 5597.8445 | G21: =QUARTILE(G$10:G$18,$B21) -> -0.00517467 | H21: =QUARTILE(H$10:H$18,$B21) -> -0.609204 | I21: =QUARTILE(I$10:I$18,$B21) -> 811.57 | J21: =QUARTILE(J$10:J$18,$B21) -> 0.06 | K21: =QUARTILE(K$10:K$18,$B21) -> 0.02279 | L21: =QUARTILE(L$10:L$18,$B21) -> 0.0156 | ... P21: =QUARTILE(P$10:P$18,$B21) -> 0.88045
C22: Median | E22: =MEDIAN(E10:E18) -> 16944.07 | F22: =MEDIAN(F10:F18) -> 16242.078 | G22: =MEDIAN(G10:G18) -> 0.0163 | H22: =MEDIAN(H10:H18) -> -0.1143 | I22: =MEDIAN(I10:I18) -> 2164.81 | J22: =MEDIAN(J10:J18) -> 0.0764 | K22: =MEDIAN(K10:K18) -> 0.0433 | L22: =MEDIAN(L10:L18) -> 0.05039 | ... P22: =MEDIAN(P10:P18) -> 1.5007
B23: =+B21+1 -> 2 | C23: Mean | E23: =QUARTILE(E$10:E$18,$B23) -> 16944.07 | F23: =QUARTILE(F$10:F$18,$B23) -> 16242.078 | G23: =QUARTILE(G$10:G$18,$B23) -> 0.0163 | H23: =QUARTILE(H$10:H$18,$B23) -> -0.1143 | I23: =QUARTILE(I$10:I$18,$B23) -> 2164.81 | J23: =QUARTILE(J$10:J$18,$B23) -> 0.0764 | K23: =QUARTILE(K$10:K$18,$B23) -> 0.0433 | L23: =QUARTILE(L$10:L$18,$B23) -> 0.05039 | ... P23: =QUARTILE(P$10:P$18,$B23) -> 1.5007
B24: =+B23+1 -> 3 | C24: Third Quartile | E24: =QUARTILE(E$10:E$18,$B24) -> 32281.302 | F24: =QUARTILE(F$10:F$18,$B24) -> 39744.525 | G24: =QUARTILE(G$10:G$18,$B24) -> 0.136835 | H24: =QUARTILE(H$10:H$18,$B24) -> 0.0884 | I24: =QUARTILE(I$10:I$18,$B24) -> 3047.1 | J24: =QUARTILE(J$10:J$18,$B24) -> 0.08815 | K24: =QUARTILE(K$10:K$18,$B24) -> 0.05465 | L24: =QUARTILE(L$10:L$18,$B24) -> 0.0895 | ... P24: =QUARTILE(P$10:P$18,$B24) -> 2.69405
B25: =+B24+1 -> 4 | C25: Maximum | E25: =QUARTILE(E$10:E$18,$B25) -> 105705.09 | F25: =QUARTILE(F$10:F$18,$B25) -> 91495.833 | G25: =QUARTILE(G$10:G$18,$B25) -> 0.255 | H25: =QUARTILE(H$10:H$18,$B25) -> 7.797 | I25: =QUARTILE(I$10:I$18,$B25) -> 7975 | J25: =QUARTILE(J$10:J$18,$B25) -> 0.2136 | K25: =QUARTILE(K$10:K$18,$B25) -> 0.2558 | L25: =QUARTILE(L$10:L$18,$B25) -> 0.116 | ... P25: =QUARTILE(P$10:P$18,$B25) -> 4.95

Sheet  Comps Valuation
C4: Valuation Comparables
H6: FY1 | I6: FY2 | J6: FY1 | K6: FY1 | L6: FY1 | M6: FY2
E7: Market | F7: Enterprise | G7: 3 year | H7: Price / | I7: Price / | J7: Price / | K7: EV / | L7: EV / | M7: EV /
C8: Company | D8: Ticker | E8: Cap | F8: Value | G8: Rev. CAGR | H8: Earnings | I8: Earnings | J8: FCF | K8: Sales | L8: EBITDA | M8: EBITDA
C10: ='Income Statement'!D3 -> GAMESTOP (NYSE: GME) | D10: ='Comps Financials'!D7 -> GME | E10: 9663.8 | F10: 5126.8 | G10: - | H10: 21.72 | I10: 26.54 | J10: 29.39 | K10: 1.23 | L10: 30.0585 | M10: 28.8
C13: ='Comps Financials'!C10 -> Best Buy Co | D13: ='Comps Financials'!D10 -> BBY-US | E13: 16944.1 | F13: 16242.1 | G13: 0.0433 | H13: 12.67 | I13: 11.78 | J13: 21.78 | K13: 0.38 | L13: 22.4 | M13: 5.9
C14: ='Comps Financials'!C11 -> JB Hi-Fi | D14: ='Comps Financials'!D11 -> JBH-AU | E14: 6873.5 | F14: 6691.5 | G14: 0.065 | H14: 20.83 | I14: 19.54 | J14: 22.86 | K14: 0.98 | L14: 22.3 | M14: 9.3
C15: ='Comps Financials'!C12 -> Woolworths Group | D15: ='Comps Financials'!D12 -> WOW-AU | E15: 22519.3 | F15: 25330.7 | G15: 0.031 | H15: 22.8 | I15: 20.27 | J15: 35.86 | K15: 0.55 | L15: 23.51 | M15: 6.8
C16: ='Comps Financials'!C13 -> target | D16: ='Comps Financials'!D13 -> TGT | E16: 42043.4 | F16: 54158.4 | G16: 0 | H16: 12.51 | I16: 11.62 | J16: 10.64 | K16: 0.52 | L16: 91.24 | M16: 6.4
C17: ='Comps Financials'!C14 -> Fnac Darty SA | D17: ='Comps Financials'!D14 -> FNAC.PA | E17: 1003.7 | F17: 2191.3 | G17: 1.452 | H17: 13.66 | I17: 10.57 | J17: 39.23 | K17: 0.18 | L17: 32.34 | M17: 2.6
C18: ='Comps Financials'!C15 -> ceconomy AG | D18: ='Comps Financials'!D15 -> CECG.DE | E18: 2504.4 | F18: 4504.2 | G18: 0 | H18: 12.93 | I18: 8.04 | J18: 770.35 | K18: 0.17 | M18: 5.2
C19: ='Comps Financials'!C16 -> Nintendo | D19: ='Comps Financials'!D16 -> NTDOY | E19: 105705.09 | F19: 91495.8 | G19: 0.076379 | H19: 40.76 | I19: 31.4 | J19: 42.72 | K19: 5.79 | L19: 90.79 | M19: 39.9
A23: 0 | C23: Minimum | E23: =QUARTILE(E$13:E$21,$A23) -> 1003.7 | F23: =QUARTILE(F$13:F$21,$A23) -> 2191.3 | G23: =QUARTILE(G$13:G$21,$A23) -> 0 | H23: =QUARTILE(H$13:H$21,$A23) -> 12.51 | I23: =QUARTILE(I$13:I$21,$A23) -> 8.04 | J23: =QUARTILE(J$13:J$21,$A23) -> 10.64 | K23: =QUARTILE(K$13:K$21,$A23) -> 0.17 | L23: =QUARTILE(L$13:L$21,$A23) -> 22.3 | M23: =QUARTILE(M$13:M$21,$A23) -> 2.6
A24: 1 | C24: First Quartile | E24: =QUARTILE(E$13:E$21,$A24) -> 4688.95 | F24: =QUARTILE(F$13:F$21,$A24) -> 5597.85 | G24: =QUARTILE(G$13:G$21,$A24) -> 0.0155 | H24: =QUARTILE(H$13:H$21,$A24) -> 12.8 | I24: =QUARTILE(I$13:I$21,$A24) -> 11.095 | J24: =QUARTILE(J$13:J$21,$A24) -> 22.32 | K24: =QUARTILE(K$13:K$21,$A24) -> 0.28 | L24: =QUARTILE(L$13:L$21,$A24) -> 22.6775 | M24: =QUARTILE(M$13:M$21,$A24) -> 5.55
C25: Mean | E25: =AVERAGE(E13:E21) -> 28227.641 | F25: =AVERAGE(F13:F21) -> 28659.143 | G25: =AVERAGE(G13:G21) -> 0.23823986 | H25: =AVERAGE(H13:H21) -> 19.451429 | I25: =AVERAGE(I13:I21) -> 16.174286 | J25: =AVERAGE(J13:J21) -> 134.77714 | K25: =AVERAGE(K13:K21) -> 1.2242857 | L25: =AVERAGE(L13:L21) -> 47.096667 | M25: =AVERAGE(M13:M21) -> 10.871429
A26: 2 | C26: Median | E26: =QUARTILE(E$13:E$21,$A26) -> 16944.1 | F26: =QUARTILE(F$13:F$21,$A26) -> 16242.1 | G26: =QUARTILE(G$13:G$21,$A26) -> 0.0433 | H26: =QUARTILE(H$13:H$21,$A26) -> 13.66 | I26: =QUARTILE(I$13:I$21,$A26) -> 11.78 | J26: =QUARTILE(J$13:J$21,$A26) -> 35.86 | K26: =QUARTILE(K$13:K$21,$A26) -> 0.52 | L26: =QUARTILE(L$13:L$21,$A26) -> 27.925 | M26: =QUARTILE(M$13:M$21,$A26) -> 6.4
A27: 3 | C27: Third Quartile | E27: =QUARTILE(E$13:E$21,$A27) -> 32281.35 | F27: =QUARTILE(F$13:F$21,$A27) -> 39744.55 | G27: =QUARTILE(G$13:G$21,$A27) -> 0.0706895 | H27: =QUARTILE(H$13:H$21,$A27) -> 21.815 | I27: =QUARTILE(I$13:I$21,$A27) -> 19.905 | J27: =QUARTILE(J$13:J$21,$A27) -> 40.975 | K27: =QUARTILE(K$13:K$21,$A27) -> 0.765 | L27: =QUARTILE(L$13:L$21,$A27) -> 76.1775 | M27: =QUARTILE(M$13:M$21,$A27) -> 8.05
A28: 4 | C28: Maximum | E28: =QUARTILE(E$13:E$21,$A28) -> 105705.09 | F28: =QUARTILE(F$13:F$21,$A28) -> 91495.8 | G28: =QUARTILE(G$13:G$21,$A28) -> 1.452 | H28: =QUARTILE(H$13:H$21,$A28) -> 40.76 | I28: =QUARTILE(I$13:I$21,$A28) -> 31.4 | J28: =QUARTILE(J$13:J$21,$A28) -> 770.35 | K28: =QUARTILE(K$13:K$21,$A28) -> 5.79 | L28: =QUARTILE(L$13:L$21,$A28) -> 91.24 | M28: =QUARTILE(M$13:M$21,$A28) -> 39.9
C31: FY1 EV/EBITDA Valuation | D31: 2025E | E31: Low/High | F31: Enterprise | G31: Net | H31: Market | I31: Shares | J31: Share
D32: EBITDA | E32: Multiple | F32: Value | G32: Debt | H32: Cap | I32: Outstanding | J32: Price
D33: =+'Income Statement'!$J$44 -> 395.234 | E33: 4.5 | F33: =+D33*E33 -> 1778.553 | G33: =+'Balance Sheet'!$H$34+'Balance Sheet'!$H$38-'Balance Sheet'!$H$11 -> 399.4 | H33: =+F33-G33 -> 1379.153 | I33: =+'Income Statement'!$I$34 -> 447 | J33: =+H33/I33 -> 3.0853535
D34: =+'Income Statement'!$J$44 -> 395.234 | E34: 5 | F34: =+D34*E34 -> 1976.17 | G34: =+'Balance Sheet'!$H$34+'Balance Sheet'!$H$38-'Balance Sheet'!$H$11 -> 399.4 | H34: =+F34-G34 -> 1576.77 | I34: =+'Income Statement'!$I$34 -> 447 | J34: =+H34/I34 -> 3.5274497
C36: FY1 Price/Earnings Valuation | D36: 2025E | E36: Low/High | F36: Enterprise | G36: Net | H36: Market | I36: Shares | J36: Stock Price
D37: Earnings | E37: Multiple | F37: Value | G37: Debt | H37: Cap | I37: Outstanding
D38: =+'Income Statement'!$J$31 -> 347.5472 | E38: 10 | H38: =+E38*D38 -> 3475.472 | I38: =+'Income Statement'!$I$34 -> 447 | J38: =+H38/I38 -> 7.7751051
D39: =+'Income Statement'!$J$31 -> 347.5472 | E39: 11 | H39: =+E39*D39 -> 3823.0192 | I39: =+'Income Statement'!$I$34 -> 447 | J39: =+H39/I39 -> 8.5526157

Sheet 3-Year Price Target Calculation
C3: ='Income Statement'!D3 -> GAMESTOP (NYSE: GME)
C4: 3 Year Price Target
C6: Needed Data | F6: Notes
C7: Current Year | D7: 2025
C8: FY1 EV/EBITDA | D8: 4.6 | F8: Hand Calculate
C9: FY1 P/E | D9: 8.1 | F9: Hand Calculate
C10: 2027 EBITDA | D10: ='Income Statement'!L44 -> 500.38465 | F10: From DCF
C11: 2027 EPS | D11: ='Income Statement'!L36 -> 0.95965117 | F11: From DCF
C12: Net Debt | D12: ='Income Statement'!I74 -> 904 | F12: Assume Debt stays at the same level
C13: # Shares Outstanding | D13: ='Income Statement'!I34 -> 447 | F13: From DCF
C15: 3-year Price Target Using EBITDA
C16: 2027 Enterprise Value | D16: =D10*D8 -> 2301.7694
C17: 2027 Equity Value | D17: =D16-D12 -> 1397.7694 | F17: = Enterprise Value - Net Debt
C18: 2027 Projected Share Price | D18: =D17/D13 -> 3.1270009 | F18: = Equity Value / # Shares Outstanding
C20: 3-year Price Target Using EPS
C21: 2027 Projected Share Price | D21: =D11*D9 -> 7.7731745 | F21: = EPS x P/E
C23: 3-Year Price Target - Blended | D23: =AVERAGE(D21,D18) -> 5.4500877
